[2022-08-27 12:25:00,359] {taskinstance.py:1179} INFO - Dependencies all met for <TaskInstance: gmailPipelineV1.gmailTbLoadTask scheduled__2022-08-26T00:00:00+00:00 [queued]>
[2022-08-27 12:25:00,378] {taskinstance.py:1179} INFO - Dependencies all met for <TaskInstance: gmailPipelineV1.gmailTbLoadTask scheduled__2022-08-26T00:00:00+00:00 [queued]>
[2022-08-27 12:25:00,378] {taskinstance.py:1376} INFO - 
--------------------------------------------------------------------------------
[2022-08-27 12:25:00,378] {taskinstance.py:1377} INFO - Starting attempt 1 of 1
[2022-08-27 12:25:00,378] {taskinstance.py:1378} INFO - 
--------------------------------------------------------------------------------
[2022-08-27 12:25:00,428] {taskinstance.py:1397} INFO - Executing <Task(PythonOperator): gmailTbLoadTask> on 2022-08-26 00:00:00+00:00
[2022-08-27 12:25:00,431] {standard_task_runner.py:52} INFO - Started process 2406 to run task
[2022-08-27 12:25:00,437] {standard_task_runner.py:79} INFO - Running: ['airflow', 'tasks', 'run', 'gmailPipelineV1', 'gmailTbLoadTask', 'scheduled__2022-08-26T00:00:00+00:00', '--job-id', '37', '--raw', '--subdir', 'DAGS_FOLDER/gmailDag.py', '--cfg-path', '/var/folders/mm/xv24gcjj46l_jx1m76p5bgy80000gn/T/tmpl7jxksl4', '--error-file', '/var/folders/mm/xv24gcjj46l_jx1m76p5bgy80000gn/T/tmpclwgr22f']
[2022-08-27 12:25:00,439] {standard_task_runner.py:80} INFO - Job 37: Subtask gmailTbLoadTask
[2022-08-27 12:25:00,494] {task_command.py:371} INFO - Running <TaskInstance: gmailPipelineV1.gmailTbLoadTask scheduled__2022-08-26T00:00:00+00:00 [running]> on host abhays-mbp.lan
[2022-08-27 12:25:00,544] {taskinstance.py:1589} INFO - Exporting the following env vars:
AIRFLOW_CTX_DAG_OWNER=airflow
AIRFLOW_CTX_DAG_ID=gmailPipelineV1
AIRFLOW_CTX_TASK_ID=gmailTbLoadTask
AIRFLOW_CTX_EXECUTION_DATE=2022-08-26T00:00:00+00:00
AIRFLOW_CTX_TRY_NUMBER=1
AIRFLOW_CTX_DAG_RUN_ID=scheduled__2022-08-26T00:00:00+00:00
[2022-08-27 12:25:00,586] {taskinstance.py:1909} ERROR - Task failed with exception
Traceback (most recent call last):
  File "/Users/abhaymone/src/dev/sand/MANAGE-GMAIL/venv/lib/python3.9/site-packages/sqlalchemy/engine/base.py", line 1782, in _execute_context
    self.dialect.do_executemany(
  File "/Users/abhaymone/src/dev/sand/MANAGE-GMAIL/venv/lib/python3.9/site-packages/sqlalchemy/dialects/mysql/mysqldb.py", line 193, in do_executemany
    rowcount = cursor.executemany(statement, parameters)
  File "/Users/abhaymone/src/dev/sand/MANAGE-GMAIL/venv/lib/python3.9/site-packages/pymysql/cursors.py", line 173, in executemany
    return self._do_execute_many(
  File "/Users/abhaymone/src/dev/sand/MANAGE-GMAIL/venv/lib/python3.9/site-packages/pymysql/cursors.py", line 211, in _do_execute_many
    rows += self.execute(sql + postfix)
  File "/Users/abhaymone/src/dev/sand/MANAGE-GMAIL/venv/lib/python3.9/site-packages/pymysql/cursors.py", line 148, in execute
    result = self._query(query)
  File "/Users/abhaymone/src/dev/sand/MANAGE-GMAIL/venv/lib/python3.9/site-packages/pymysql/cursors.py", line 310, in _query
    conn.query(q)
  File "/Users/abhaymone/src/dev/sand/MANAGE-GMAIL/venv/lib/python3.9/site-packages/pymysql/connections.py", line 548, in query
    self._affected_rows = self._read_query_result(unbuffered=unbuffered)
  File "/Users/abhaymone/src/dev/sand/MANAGE-GMAIL/venv/lib/python3.9/site-packages/pymysql/connections.py", line 775, in _read_query_result
    result.read()
  File "/Users/abhaymone/src/dev/sand/MANAGE-GMAIL/venv/lib/python3.9/site-packages/pymysql/connections.py", line 1156, in read
    first_packet = self.connection._read_packet()
  File "/Users/abhaymone/src/dev/sand/MANAGE-GMAIL/venv/lib/python3.9/site-packages/pymysql/connections.py", line 725, in _read_packet
    packet.raise_for_error()
  File "/Users/abhaymone/src/dev/sand/MANAGE-GMAIL/venv/lib/python3.9/site-packages/pymysql/protocol.py", line 221, in raise_for_error
    err.raise_mysql_exception(self._data)
  File "/Users/abhaymone/src/dev/sand/MANAGE-GMAIL/venv/lib/python3.9/site-packages/pymysql/err.py", line 143, in raise_mysql_exception
    raise errorclass(errno, errval)
pymysql.err.IntegrityError: (1062, "Duplicate entry '182c8ab78f6dfdf4' for key 'gmailmsgs.PRIMARY'")

The above exception was the direct cause of the following exception:

Traceback (most recent call last):
  File "/Users/abhaymone/src/dev/sand/MANAGE-GMAIL/venv/lib/python3.9/site-packages/airflow/operators/python.py", line 171, in execute
    return_value = self.execute_callable()
  File "/Users/abhaymone/src/dev/sand/MANAGE-GMAIL/venv/lib/python3.9/site-packages/airflow/operators/python.py", line 189, in execute_callable
    return self.python_callable(*self.op_args, **self.op_kwargs)
  File "/Users/abhaymone/src/dev/sand/MANAGE-GMAIL/dags/gmailDag.py", line 40, in pullGmailLoad
    tbLoad.gmailMsgLoad()
  File "/Users/abhaymone/src/dev/sand/MANAGE-GMAIL/gmailLoad.py", line 11, in gmailMsgLoad
    self.gmailMsgDF.to_sql('gmailMsgs',self.sqlconn,if_exists='append', index=False )
  File "/Users/abhaymone/src/dev/sand/MANAGE-GMAIL/venv/lib/python3.9/site-packages/pandas/core/generic.py", line 2951, in to_sql
    return sql.to_sql(
  File "/Users/abhaymone/src/dev/sand/MANAGE-GMAIL/venv/lib/python3.9/site-packages/pandas/io/sql.py", line 697, in to_sql
    return pandas_sql.to_sql(
  File "/Users/abhaymone/src/dev/sand/MANAGE-GMAIL/venv/lib/python3.9/site-packages/pandas/io/sql.py", line 1739, in to_sql
    total_inserted = sql_engine.insert_records(
  File "/Users/abhaymone/src/dev/sand/MANAGE-GMAIL/venv/lib/python3.9/site-packages/pandas/io/sql.py", line 1332, in insert_records
    raise err
  File "/Users/abhaymone/src/dev/sand/MANAGE-GMAIL/venv/lib/python3.9/site-packages/pandas/io/sql.py", line 1322, in insert_records
    return table.insert(chunksize=chunksize, method=method)
  File "/Users/abhaymone/src/dev/sand/MANAGE-GMAIL/venv/lib/python3.9/site-packages/pandas/io/sql.py", line 950, in insert
    num_inserted = exec_insert(conn, keys, chunk_iter)
  File "/Users/abhaymone/src/dev/sand/MANAGE-GMAIL/venv/lib/python3.9/site-packages/pandas/io/sql.py", line 857, in _execute_insert
    result = conn.execute(self.table.insert(), data)
  File "/Users/abhaymone/src/dev/sand/MANAGE-GMAIL/venv/lib/python3.9/site-packages/sqlalchemy/engine/base.py", line 1289, in execute
    return meth(self, multiparams, params, _EMPTY_EXECUTION_OPTS)
  File "/Users/abhaymone/src/dev/sand/MANAGE-GMAIL/venv/lib/python3.9/site-packages/sqlalchemy/sql/elements.py", line 325, in _execute_on_connection
    return connection._execute_clauseelement(
  File "/Users/abhaymone/src/dev/sand/MANAGE-GMAIL/venv/lib/python3.9/site-packages/sqlalchemy/engine/base.py", line 1481, in _execute_clauseelement
    ret = self._execute_context(
  File "/Users/abhaymone/src/dev/sand/MANAGE-GMAIL/venv/lib/python3.9/site-packages/sqlalchemy/engine/base.py", line 1845, in _execute_context
    self._handle_dbapi_exception(
  File "/Users/abhaymone/src/dev/sand/MANAGE-GMAIL/venv/lib/python3.9/site-packages/sqlalchemy/engine/base.py", line 2026, in _handle_dbapi_exception
    util.raise_(
  File "/Users/abhaymone/src/dev/sand/MANAGE-GMAIL/venv/lib/python3.9/site-packages/sqlalchemy/util/compat.py", line 207, in raise_
    raise exception
  File "/Users/abhaymone/src/dev/sand/MANAGE-GMAIL/venv/lib/python3.9/site-packages/sqlalchemy/engine/base.py", line 1782, in _execute_context
    self.dialect.do_executemany(
  File "/Users/abhaymone/src/dev/sand/MANAGE-GMAIL/venv/lib/python3.9/site-packages/sqlalchemy/dialects/mysql/mysqldb.py", line 193, in do_executemany
    rowcount = cursor.executemany(statement, parameters)
  File "/Users/abhaymone/src/dev/sand/MANAGE-GMAIL/venv/lib/python3.9/site-packages/pymysql/cursors.py", line 173, in executemany
    return self._do_execute_many(
  File "/Users/abhaymone/src/dev/sand/MANAGE-GMAIL/venv/lib/python3.9/site-packages/pymysql/cursors.py", line 211, in _do_execute_many
    rows += self.execute(sql + postfix)
  File "/Users/abhaymone/src/dev/sand/MANAGE-GMAIL/venv/lib/python3.9/site-packages/pymysql/cursors.py", line 148, in execute
    result = self._query(query)
  File "/Users/abhaymone/src/dev/sand/MANAGE-GMAIL/venv/lib/python3.9/site-packages/pymysql/cursors.py", line 310, in _query
    conn.query(q)
  File "/Users/abhaymone/src/dev/sand/MANAGE-GMAIL/venv/lib/python3.9/site-packages/pymysql/connections.py", line 548, in query
    self._affected_rows = self._read_query_result(unbuffered=unbuffered)
  File "/Users/abhaymone/src/dev/sand/MANAGE-GMAIL/venv/lib/python3.9/site-packages/pymysql/connections.py", line 775, in _read_query_result
    result.read()
  File "/Users/abhaymone/src/dev/sand/MANAGE-GMAIL/venv/lib/python3.9/site-packages/pymysql/connections.py", line 1156, in read
    first_packet = self.connection._read_packet()
  File "/Users/abhaymone/src/dev/sand/MANAGE-GMAIL/venv/lib/python3.9/site-packages/pymysql/connections.py", line 725, in _read_packet
    packet.raise_for_error()
  File "/Users/abhaymone/src/dev/sand/MANAGE-GMAIL/venv/lib/python3.9/site-packages/pymysql/protocol.py", line 221, in raise_for_error
    err.raise_mysql_exception(self._data)
  File "/Users/abhaymone/src/dev/sand/MANAGE-GMAIL/venv/lib/python3.9/site-packages/pymysql/err.py", line 143, in raise_mysql_exception
    raise errorclass(errno, errval)
sqlalchemy.exc.IntegrityError: (pymysql.err.IntegrityError) (1062, "Duplicate entry '182c8ab78f6dfdf4' for key 'gmailmsgs.PRIMARY'")
[SQL: INSERT INTO `gmailMsgs` (`MSG_ID`, `RECEIVE_DT`, `FRM_EMAIL`) VALUES (%(MSG_ID)s, %(RECEIVE_DT)s, %(FRM_EMAIL)s)]
[parameters: ({'MSG_ID': '182dcaacbd08ef77', 'RECEIVE_DT': '2022-08-26', 'FRM_EMAIL': 'noreply-photos@google.com'}, {'MSG_ID': '182dc548ae0563a5', 'RECEIVE_DT': '2022-08-26', 'FRM_EMAIL': 'no.reply.alerts@chase.com'}, {'MSG_ID': '182dbdede2568584', 'RECEIVE_DT': '2022-08-26', 'FRM_EMAIL': 'chase@email.chase.com'}, {'MSG_ID': '182db61eebc1d9ce', 'RECEIVE_DT': '2022-08-26', 'FRM_EMAIL': 'donotreply@upwork.com'}, {'MSG_ID': '182da13f445eaa9c', 'RECEIVE_DT': '2022-08-26', 'FRM_EMAIL': 'mint@em1.mint.intuit.com'}, {'MSG_ID': '182d855df241128a', 'RECEIVE_DT': '2022-08-26', 'FRM_EMAIL': 'hello@splitwise.com'}, {'MSG_ID': '182d733b6f351622', 'RECEIVE_DT': '2022-08-25', 'FRM_EMAIL': 'no.reply.alerts@chase.com'}, {'MSG_ID': '182d733b4bebf594', 'RECEIVE_DT': '2022-08-25', 'FRM_EMAIL': 'no.reply.alerts@chase.com'}  ... displaying 10 of 28 total bound parameter sets ...  {'MSG_ID': '182c57afa0026097', 'RECEIVE_DT': '2022-08-22', 'FRM_EMAIL': 'noreply@wise.com'}, {'MSG_ID': '182c551177954b26', 'RECEIVE_DT': '2022-08-22', 'FRM_EMAIL': 'noreply@medium.com'})]
(Background on this error at: https://sqlalche.me/e/14/gkpj)
[2022-08-27 12:25:00,596] {taskinstance.py:1415} INFO - Marking task as FAILED. dag_id=gmailPipelineV1, task_id=gmailTbLoadTask, execution_date=20220826T000000, start_date=20220827T162500, end_date=20220827T162500
[2022-08-27 12:25:00,603] {standard_task_runner.py:92} ERROR - Failed to execute job 37 for task gmailTbLoadTask ((pymysql.err.IntegrityError) (1062, "Duplicate entry '182c8ab78f6dfdf4' for key 'gmailmsgs.PRIMARY'")
[SQL: INSERT INTO `gmailMsgs` (`MSG_ID`, `RECEIVE_DT`, `FRM_EMAIL`) VALUES (%(MSG_ID)s, %(RECEIVE_DT)s, %(FRM_EMAIL)s)]
[parameters: ({'MSG_ID': '182dcaacbd08ef77', 'RECEIVE_DT': '2022-08-26', 'FRM_EMAIL': 'noreply-photos@google.com'}, {'MSG_ID': '182dc548ae0563a5', 'RECEIVE_DT': '2022-08-26', 'FRM_EMAIL': 'no.reply.alerts@chase.com'}, {'MSG_ID': '182dbdede2568584', 'RECEIVE_DT': '2022-08-26', 'FRM_EMAIL': 'chase@email.chase.com'}, {'MSG_ID': '182db61eebc1d9ce', 'RECEIVE_DT': '2022-08-26', 'FRM_EMAIL': 'donotreply@upwork.com'}, {'MSG_ID': '182da13f445eaa9c', 'RECEIVE_DT': '2022-08-26', 'FRM_EMAIL': 'mint@em1.mint.intuit.com'}, {'MSG_ID': '182d855df241128a', 'RECEIVE_DT': '2022-08-26', 'FRM_EMAIL': 'hello@splitwise.com'}, {'MSG_ID': '182d733b6f351622', 'RECEIVE_DT': '2022-08-25', 'FRM_EMAIL': 'no.reply.alerts@chase.com'}, {'MSG_ID': '182d733b4bebf594', 'RECEIVE_DT': '2022-08-25', 'FRM_EMAIL': 'no.reply.alerts@chase.com'}  ... displaying 10 of 28 total bound parameter sets ...  {'MSG_ID': '182c57afa0026097', 'RECEIVE_DT': '2022-08-22', 'FRM_EMAIL': 'noreply@wise.com'}, {'MSG_ID': '182c551177954b26', 'RECEIVE_DT': '2022-08-22', 'FRM_EMAIL': 'noreply@medium.com'})]
(Background on this error at: https://sqlalche.me/e/14/gkpj); 2406)
[2022-08-27 12:25:00,639] {local_task_job.py:156} INFO - Task exited with return code 1
[2022-08-27 12:25:00,660] {local_task_job.py:273} INFO - 0 downstream tasks scheduled from follow-on schedule check
